<!DOCTYPE html>
<html lang="en">
<head>
	<meta charset="UTF-8">
	<title>async6</title>
</head>
<style>
	pre{
		height: auto;
		color: #ccc;
		background: black;
	}
</style>
<script>
	async function f(){
		return await 123;
		//因为是数值，所以转成promise对象，并且立即resolve
	}
	f().then(v=>console.log(v))

	//有时，我们希望即使前一个异步操作失败，也不要中断后面的异步操作。这时可以将第一个await放在try...catch结构里面，这样不管这个异步操作是否成功，第二个await都会执行。
	async function f() {
	  try {
	    await Promise.reject('出错了');
	  } catch(e) {
	  }
	  return await Promise.resolve('hello world');
	}

	f()
	.then(v => console.log(v))
	//hello world
</script>
<body>
	<p>正常情况下，await命令后面是一个 Promise 对象。如果不是，会被转成一个立即resolve的 Promise 对象。</p>
//注意，上面代码中，await语句前面没有return，但是reject方法的参数依然传入了catch方法的回调函数。这里如果在await前面加上return，效果是一样的。

只要一个await语句后面的 Promise 变为reject，那么整个async函数都会中断执行。

<p>希望第一个异步即便失败，也可以继续后面的操作，可以用try...catch方式，将await函数放在try里面，或者是在await后面的promise对象跟一个catch方法处理前面的错误</p>
<pre>如：async function main() {
  try {
    const val1 = await firstStep();
    const val2 = await secondStep(val1);
    const val3 = await thirdStep(val1, val2);

    console.log('Final: ', val3);
  }
  catch (err) {
    console.error(err);
  }
}</pre>

<pre>##const superagent = require('superagent');
const NUM_RETRIES = 3;

async function test() {
  let i;
  for (i = 0; i < NUM_RETRIES; ++i) {
    try {
      await superagent.get('http://google.com/this-throws-an-error');
      break;
    } catch(err) {}
  }
  console.log(i); // 3
}

test();
上面代码中，如果await操作成功，就会使用break语句退出循环；如果失败，会被catch语句捕捉，然后进入下一轮循环。
</pre></body>
</html>